<?xml version="1.0" encoding="utf-8"?>
<!-- This URDF was automatically created by SolidWorks to URDF Exporter! Originally created by Stephen Brawner (brawner@gmail.com) 
     Commit Version: 1.5.1-0-g916b5db  Build Version: 1.5.7152.31018
     For more information, please see http://wiki.ros.org/sw_urdf_exporter -->
<robot xmlns:xacro="http://www.ros.org/wiki/xacro"  name="ant_model">
    
    <xacro:property name="body_width"  value="0.00097" />
    <xacro:property name="body_length" value="0.00188" />
    <xacro:property name="body_height" value="0.001" />
    
    <xacro:property name="body_mass" value="0.001" />
    <xacro:property name="segment_mass" value="0.0001" />
    
    <xacro:property name="l1_f" value="0.0006" />
    <xacro:property name="l2_f" value="0.00320" />
    <xacro:property name="l3_f" value="0.00320" />
    <xacro:property name="l4_f" value="0.00530" />
    <xacro:property name="l1_m" value="0.00038" />
    <xacro:property name="l2_m" value="0.00138" />
    <xacro:property name="l3_m" value="0.00121" />
    <xacro:property name="l4_m" value="0.00159" />
    <xacro:property name="l1_b" value="0.00044" />
    <xacro:property name="l2_b" value="0.00161" />
    <xacro:property name="l3_b" value="0.00146" />
    <xacro:property name="l4_b" value="0.00195" />
    <xacro:property name="l_width" value="0.0001" />
    <xacro:property name="f_width" value="0.0001" />
   

    <xacro:property name="l1_pos_x" value="0.0005"  />
    <xacro:property name="l1_pos_y" value="0.0005"  />
    <xacro:property name="l2_pos_x" value="0"  />
    <xacro:property name="l2_pos_y" value="0.0005"  />
    <xacro:property name="l3_pos_x" value="-0.0005"  />
    <xacro:property name="l3_pos_y" value="0.0005"  />
    <xacro:property name="damping" value="0.02"  />
    <xacro:property name="body_inertia" value="1e-6"  />    
    
    <link name="base_link" />
    
    <joint name="fix_joint" type="fixed">
      <origin xyz="0 0 0" rpy="0 0 0" />
      <parent link="base_link" />
      <child link="body_link" />
    </joint>
    
   <link
    name="body_link">
    <inertial>
      <mass
        value="${body_mass}" />
      <inertia ixx="${body_inertia}" ixy="0" ixz="0" iyy="${body_inertia}" iyz="0" izz="${body_inertia}" />
    </inertial>
    <visual>
      <geometry>
        <box size="${body_length} ${body_width} ${body_height}"/>
      </geometry>
      <material
        name="">
        <color
          rgba="0.792156862745098 0.819607843137255 0.933333333333333 1" />
      </material>
    </visual>
    <collision>
      <geometry>
        <box size="${body_length} ${body_width} ${body_height}"/>
      </geometry>
    </collision>
  </link>
  <gazebo reference="body_link">
    <mu1>1</mu1>
    <mu2>1</mu2>
    <material>Gazebo/Black</material>
  </gazebo>

   
   <link
    name="head_link">
    <inertial>
      <mass
        value="${body_mass*0.2}" />
      <inertia ixx="${body_inertia*0.1}" ixy="0" ixz="0" iyy="${body_inertia*0.1}" iyz="0" izz="${body_inertia*0.1}" />
    </inertial>
    <visual>
      <geometry>
        <sphere radius="${body_length/4}"/>
      </geometry>
      <material
        name="">
        <color
          rgba="0.792156862745098 0.819607843137255 0.933333333333333 1" />
      </material>
    </visual>
    <collision>
      <geometry>
        <sphere radius="${body_length/4}"/>
      </geometry>
    </collision>
  </link>
  <gazebo reference="head_link">
    <mu1>1</mu1>
    <mu2>1</mu2>
    <material>Gazebo/Black</material>
  </gazebo>
    <joint name="head_joint" type="fixed">
      <origin xyz="${4*body_length/8+0.001} 0 0" rpy="0 0 0" />
      <parent link="body_link" />
      <child link="head_link" />
    </joint>


   <link
    name="abdomen_link">
    <inertial>
      <mass
        value="${body_mass*0.3}" />
      <inertia ixx="${body_inertia*0.1}" ixy="0" ixz="0" iyy="${body_inertia*0.1}" iyz="0" izz="${body_inertia*0.1}" />
    </inertial>
    <visual>
      <geometry>
        <sphere radius="${body_length/3}"/>
      </geometry>
      <material
        name="">
        <color
          rgba="0.792156862745098 0.819607843137255 0.933333333333333 1" />
      </material>
    </visual>
    <collision>
      <geometry>
        <sphere radius="${body_length/3}"/>
      </geometry>
    </collision>
  </link>
  <gazebo reference="abdomen_link">
    <mu1>1</mu1>
    <mu2>1</mu2>
    <material>Gazebo/Black</material>
  </gazebo>
    <joint name="abdomen_joint" type="fixed">
      <origin xyz="${-4*body_length/8-0.001} 0 0" rpy="0 0 0" />
      <parent link="body_link" />
      <child link="abdomen_link" />
    </joint>
    
    
    
      <material name="blue">
    <color rgba="0 0 1 1"/>
  </material>

  <material name="green">
    <color rgba="0 1 0 1"/>
  </material>
  
    <material name="red">
    <color rgba="1 0 0  1"/>
  </material>

  <material name="yellow">
    <color rgba="1 1 0 1"/>
  </material>
  
  <xacro:macro name="leg" params="name dx dy l1 l2 l3 l4 direction">
     <link
    name="${name}1_link">
    <inertial>
      <mass
        value="${segment_mass}" />
      <inertia ixx="${body_inertia*0.01}" ixy="0" ixz="0" iyy="${body_inertia*0.01}" iyz="0" izz="${body_inertia*0.01}" />
    </inertial>
    <visual>
      <geometry>
         <box size="${l1} ${l_width} ${l_width}"/>
      </geometry>
        <origin xyz="0 0 0" rpy="0 0 0" />
      <material
        name="red">

      </material>
    </visual>
    <collision>
      <geometry>
         <box size="${l1} ${l_width} ${l_width}"/>
      </geometry>
        <origin xyz="${l1*0.5} 0 0" rpy="0 0 0" />
    </collision>
  </link>
    <joint
    name="${name}1_joint"
    type="continuous">
    <origin
      xyz="${dx} ${dy} ${body_height*0.5 + l_width*0.5+0.0001}"
      rpy="0 0 ${direction}" />
    <parent
      link="body_link" />
    <child
      link="${name}1_link" />
    <axis
      xyz="0 0 1" />
  </joint>
   <transmission name="${name}1_trans">
    <type>transmission_interface/SimpleTransmission</type>
    <actuator name="${name}1_motor">
      <mechanicalReduction>1</mechanicalReduction>
    </actuator>
    <joint name="${name}1_joint">
      <hardwareInterface>hardware_interface/PositionJointInterface</hardwareInterface>
    </joint>
  </transmission>
      <gazebo reference="${name}1_link">
    <mu1>3</mu1>
    <mu2>3</mu2>
    <material>Gazebo/Black</material>
    <dampingFactor>${damping}</dampingFactor>
  </gazebo>
      <link
    name="${name}2_link">
    <inertial>
      <mass
        value="${segment_mass}" />
      <inertia ixx="${body_inertia*0.01}" ixy="0" ixz="0" iyy="${body_inertia*0.01}" iyz="0" izz="${body_inertia*0.01}" />
    </inertial>
    <visual>
      <geometry>
         <box size="${l2} ${l_width} ${l_width}"/>
      </geometry>
        <origin xyz="0 0 0" rpy="0 0 0" />
      <material
        name="green">

      </material>
    </visual>
    <collision>
      <geometry>
         <box size="${l2} ${l_width} ${l_width}"/>
      </geometry>
        <origin xyz="${l2*0.5} 0 0" rpy="0 0 0" />
    </collision>
  </link>
    <joint
    name="${name}2_joint"
    type="continuous">
    <origin
      xyz="${l1+l_width*0.5} 0 0"
      rpy="0 0 0" />
    <parent
      link="${name}1_link" />
    <child
      link="${name}2_link" />
    <axis
      xyz="0 1 0" />
  </joint>
    <transmission name="${name}2_trans">
    <type>transmission_interface/SimpleTransmission</type>
    <actuator name="${name}2_motor">
      <mechanicalReduction>1</mechanicalReduction>
    </actuator>
    <joint name="${name}2_joint">
      <hardwareInterface>hardware_interface/PositionJointInterface</hardwareInterface>
    </joint>
    </transmission>
    <gazebo reference="${name}2_link">
    <mu1>3</mu1>
    <mu2>3</mu2>
    <material>Gazebo/Black</material>
    <dampingFactor>${damping}</dampingFactor>
  </gazebo>

        <link
    name="${name}3_link">
    <inertial>
      <mass
        value="${segment_mass}" />
      <inertia ixx="${body_inertia*0.01}" ixy="0" ixz="0" iyy="${body_inertia*0.01}" iyz="0" izz="${body_inertia*0.01}" />
    </inertial>
    <visual>
      <geometry>
         <box size="${l3} ${l_width} ${l_width}"/>
      </geometry>
        <origin xyz="0 0 0" rpy="0 0 0" />
      <material
        name="blue">

      </material>
    </visual>
    <collision>
      <geometry>
         <box size="${l3} ${l_width} ${l_width}"/>
      </geometry>
        <origin xyz="${l3*0.5} 0 0" rpy="0 0 0" />
    </collision>
  </link>
    <joint
    name="${name}3_joint"
    type="continuous">
    <origin
      xyz="${l2+l_width*0.5} 0 0"
      rpy="0 0 0" />
    <parent
      link="${name}2_link" />
    <child
      link="${name}3_link" />
    <axis
      xyz="0 1 0" />
  </joint>
    <transmission name="${name}3_trans">
    <type>transmission_interface/SimpleTransmission</type>
    <actuator name="${name}3_motor">
      <mechanicalReduction>1</mechanicalReduction>
    </actuator>
    <joint name="${name}3_joint">
      <hardwareInterface>hardware_interface/PositionJointInterface</hardwareInterface>
    </joint>
  </transmission>
    <gazebo reference="${name}3_link">
    <mu1>3</mu1>
    <mu2>3</mu2>
    <material>Gazebo/Black</material>
    <dampingFactor>${damping}</dampingFactor>
  </gazebo>

  <link
    name="${name}4_link">
    <inertial>
      <mass
        value="${segment_mass}" />
      <inertia ixx="${body_inertia*0.01}" ixy="0" ixz="0" iyy="${body_inertia*0.01}" iyz="0" izz="${body_inertia*0.01}" />
    </inertial>
    <visual>
      <geometry>
         <box size="${l4} ${l_width} ${f_width}"/>
      </geometry>
        <origin xyz="0 0 0" rpy="0 0 0" />
      <material
        name="yellow">

      </material>
    </visual>
    <collision>
      <geometry>
         <box size="${l4} ${l_width} ${f_width}"/>
      </geometry>
        <origin xyz="${l4*0.5} 0 0" rpy="0 0 0" />
    </collision>
  </link>
    <joint
    name="${name}4_joint"
    type="continuous">
    <origin
      xyz="${l3+l_width*0.5} 0 0"
      rpy="0 0 0" />
    <parent
      link="${name}3_link" />
    <child
      link="${name}4_link" />
    <axis
      xyz="0 1 0" />
    <!--dynamics damping="0.000007"/-->
  </joint>
    <transmission name="${name}4_trans">
    <type>transmission_interface/SimpleTransmission</type>
    <actuator name="${name}4_motor">
      <mechanicalReduction>1</mechanicalReduction>
    </actuator>
    <joint name="${name}4_joint">
      <hardwareInterface>hardware_interface/PositionJointInterface</hardwareInterface>
    </joint>
  </transmission>
  <gazebo reference="${name}4_link">
    <mu1>5</mu1>
    <mu2>5</mu2>
    <material>Gazebo/Black</material>
    <dampingFactor>${damping}</dampingFactor>
  </gazebo>
 
  </xacro:macro>
  
    <xacro:leg name="left_forward" dx="${l1_pos_x}" dy="${l1_pos_y}" l1="${l1_f}" l2="${l2_f}" l3="${l3_f}" l4="${l4_f}"  direction="${pi/2}" />
    <xacro:leg name="right_forward" dx="${l1_pos_x}" dy="${-l1_pos_y}" l1="${l1_f}" l2="${l2_f}" l3="${l3_f}" l4="${l4_f}" direction="${-pi/2}"/>
    <xacro:leg name="left_middle" dx="${l2_pos_x}" dy="${l2_pos_y}" l1="${l1_f}" l2="${l2_f}" l3="${l3_f}" l4="${l4_f}" direction="${pi/2}"/>
    <xacro:leg name="right_middle" dx="${l2_pos_x}" dy="${-l2_pos_y}" l1="${l1_f}" l2="${l2_f}" l3="${l3_f}" l4="${l4_f}"  direction="${-pi/2}" />
    <xacro:leg name="left_backward" dx="${l3_pos_x}" dy="${l3_pos_y}" l1="${l1_f}" l2="${l2_f}" l3="${l3_f}" l4="${l4_f}" direction="${pi/2}" />
    <xacro:leg name="right_backward" dx="${l3_pos_x}" dy="${-l3_pos_y}" l1="${l1_f}" l2="${l2_f}" l3="${l3_f}" l4="${l4_f}" direction="${-pi/2}" />
    
    <gazebo>
    <plugin name="gazebo_ros_control" filename="libgazebo_ros_control.so">
      <robotNamespace>/</robotNamespace>
    </plugin>
  </gazebo>  
  
  
  <camera name="camera">
  <pose>0 0 0.1 0 0 0</pose>
  <sensor type="camera" name="camera">
    <camera>
      <horizontal_fov>1.047</horizontal_fov>
      <image>
        <width>640</width>
        <height>480</height>
        <format>R8G8B8</format>
      </image>
      <clip>
        <near>0.1</near>
        <far>100</far>
      </clip>
      <noise>
        <type>gaussian</type>
        <mean>0.0</mean>
        <stddev>0.01</stddev>
      </noise>
    </camera>
    <update_rate>30.0</update_rate>
    <always_on>true</always_on>
    <visualize>true</visualize>
  </sensor>
</camera>
  

    
</robot>
